Workbook

Sheet Projet
A1: BLOKIWOOD — Demande de chiffrage d'un kit structure bois
A2: Chaque kit est calculé et fabriqué sur mesure pour votre projet. Un chiffrage fiable demande plusieurs heures d'étude et de calcul de structure : merci de compléter ce dossier le plus précisément possible et de nous le retourner avec vos plans.
A3: Légende | B3: Case à compléter | C3: * = information indispensable au chiffrage (case orangée tant qu'elle est vide)
A4: Dossier complété à | B4: =IFERROR(SUMPRODUCT(($D$7:$D$98=1)*($B$7:$B$98<>""))/SUM($D$7:$D$98),0) | C4: Onglets à remplir : 1. Projet · 2. Ouvertures · 3. Façades & planchers
A6: 1. Vos coordonnées
A7: Nom et prénom * | D7: 1
A8: Société (si professionnel)
A9: Téléphone * | C9: Ex. : 06 12 34 56 78 | D9: 1
A10: E-mail * | D10: 1
A11: Adresse actuelle
A13: 2. Le terrain
A14: Adresse du terrain * | C14: Rue / lieu-dit | D14: 1
A15: Code postal et commune * | C15: Ex. : 44000 Nantes | D15: 1
A16: Référence cadastrale * | C16: Section + n° de parcelle, ex. : AB 123 (cadastre.gouv.fr) | D16: 1
A17: Statut du terrain * | D17: 1
A18: Surface du terrain (m²)
A19: Pente du terrain * | D19: 1
A20: Terrain viabilisé (eau, électricité) * | D20: 1
A21: Assainissement
A23: 3. Avancement du projet
A24: Niveau d'avancement * | C24: PC = permis de construire | D24: 1
A25: N° du permis de construire | C25: Si déposé ou obtenu, ex. : PC 044 109 25 X0012
A26: Date de dépôt ou d'obtention du PC | C26: Format jj/mm/aaaa
A27: Architecte / maître d'œuvre (nom) | C27: Laisser vide si aucun
A28: Étude de sol G2 * | C28: Obligatoire en zone argileuse (loi ELAN) | D28: 1
A29: Étude thermique RE2020 * | D29: 1
A31: 4. Montage du kit
A32: Qui montera le kit ? * | D32: 1
A33: Nom de l'artisan / entreprise de pose | C33: Si déjà choisi
A34: Expérience en construction du monteur * | D34: 1
A36: 5. Financement
A37: Budget global du projet TTC (€) * | C37: Maison complète, hors terrain | D37: 1
A38: Mode de financement * | D38: 1
A39: Accord de principe bancaire | C39: Si prêt bancaire ou mixte
A40: Assurance dommages-ouvrage * | D40: 1
A42: 6. Planning
A43: Date souhaitée de début des fondations * | C43: Format jj/mm/aaaa | D43: 1
A44: Date souhaitée de livraison du kit * | C44: Format jj/mm/aaaa | D44: 1
A45: Autres devis demandés pour ce projet
A46: Date prévue de votre décision | C46: Format jj/mm/aaaa
...

Sheet Ouvertures
A1: Tableau des ouvertures (réservations à prévoir dans le kit)
A2: Une ligne par ouverture (ou par groupe d'ouvertures identiques sur la même façade). Cotes en millimètres. La ligne grisée est un exemple et n'est pas prise en compte. La colonne « Contrôle » signale les incohérences.
A4: Repère | B4: Niveau | C4: Façade | D4: Pièce | E4: Type d'ouverture | F4: Largeur (mm) | G4: Hauteur (mm) | H4: Hauteur d'allège (mm) | I4: Distance depuis l'angle gauche (mm) | J4: Cotes données en | K4: Volet | L4: Quantité | M4: Surface unitaire (m²) | N4: Surface totale (m²) | O4: Contrôle
A5: F1 | B5: RDC | C5: Sud | D5: Séjour | E5: Baie coulissante | F5: 2400 | G5: 2150 | H5: 0 | I5: 1200 | J5: Tableau (trou fini) | K5: Roulant motorisé | L5: 1 | M5: =IF(AND(ISNUMBER(F5),ISNUMBER(G5)),F5*G5/1000000,"") | N5: =IF(M5="","",M5*IF(ISNUMBER(L5),L5,1)) | O5: =IF(COUNTA(A5:L5)=0,"",IF(OR(NOT(ISNUMBER(F5)),NOT(ISNUMBER(G5))),"⚠ Largeur ou hauteur manquante",IF(C5="","⚠ Façade manquante",IF(AND(OR(E5="Fenêtre",E5="Châssis fixe"),NOT(ISNUMBER(H5))),"⚠ Hauteur d'allège manquante",IF(AND(E5<>"Fenêtre de toit",IF($B5="R+1",N(Projet!$B$61),N(Projet!$B$60))>0,N(H5)+G5>IF($B5="R+1",N(Projet!$B$61),N(Projet!$B$60))*1000),"⚠ Dépasse la hauteur sous plafond",IF(J5="","⚠ Préciser tableau / hors tout","OK")))))) | P5: ← exemple
M6: =IF(AND(ISNUMBER(F6),ISNUMBER(G6)),F6*G6/1000000,"") | N6: =IF(M6="","",M6*IF(ISNUMBER(L6),L6,1)) | O6: =IF(COUNTA(A6:L6)=0,"",IF(OR(NOT(ISNUMBER(F6)),NOT(ISNUMBER(G6))),"⚠ Largeur ou hauteur manquante",IF(C6="","⚠ Façade manquante",IF(AND(OR(E6="Fenêtre",E6="Châssis fixe"),NOT(ISNUMBER(H6))),"⚠ Hauteur d'allège manquante",IF(AND(E6<>"Fenêtre de toit",IF($B6="R+1",N(Projet!$B$61),N(Projet!$B$60))>0,N(H6)+G6>IF($B6="R+1",N(Projet!$B$61),N(Projet!$B$60))*1000),"⚠ Dépasse la hauteur sous plafond",IF(J6="","⚠ Préciser tableau / hors tout","OK"))))))
M7: =IF(AND(ISNUMBER(F7),ISNUMBER(G7)),F7*G7/1000000,"") | N7: =IF(M7="","",M7*IF(ISNUMBER(L7),L7,1)) | O7: =IF(COUNTA(A7:L7)=0,"",IF(OR(NOT(ISNUMBER(F7)),NOT(ISNUMBER(G7))),"⚠ Largeur ou hauteur manquante",IF(C7="","⚠ Façade manquante",IF(AND(OR(E7="Fenêtre",E7="Châssis fixe"),NOT(ISNUMBER(H7))),"⚠ Hauteur d'allège manquante",IF(AND(E7<>"Fenêtre de toit",IF($B7="R+1",N(Projet!$B$61),N(Projet!$B$60))>0,N(H7)+G7>IF($B7="R+1",N(Projet!$B$61),N(Projet!$B$60))*1000),"⚠ Dépasse la hauteur sous plafond",IF(J7="","⚠ Préciser tableau / hors tout","OK"))))))
M8: =IF(AND(ISNUMBER(F8),ISNUMBER(G8)),F8*G8/1000000,"") | N8: =IF(M8="","",M8*IF(ISNUMBER(L8),L8,1)) | O8: =IF(COUNTA(A8:L8)=0,"",IF(OR(NOT(ISNUMBER(F8)),NOT(ISNUMBER(G8))),"⚠ Largeur ou hauteur manquante",IF(C8="","⚠ Façade manquante",IF(AND(OR(E8="Fenêtre",E8="Châssis fixe"),NOT(ISNUMBER(H8))),"⚠ Hauteur d'allège manquante",IF(AND(E8<>"Fenêtre de toit",IF($B8="R+1",N(Projet!$B$61),N(Projet!$B$60))>0,N(H8)+G8>IF($B8="R+1",N(Projet!$B$61),N(Projet!$B$60))*1000),"⚠ Dépasse la hauteur sous plafond",IF(J8="","⚠ Préciser tableau / hors tout","OK"))))))
M9: =IF(AND(ISNUMBER(F9),ISNUMBER(G9)),F9*G9/1000000,"") | N9: =IF(M9="","",M9*IF(ISNUMBER(L9),L9,1)) | O9: =IF(COUNTA(A9:L9)=0,"",IF(OR(NOT(ISNUMBER(F9)),NOT(ISNUMBER(G9))),"⚠ Largeur ou hauteur manquante",IF(C9="","⚠ Façade manquante",IF(AND(OR(E9="Fenêtre",E9="Châssis fixe"),NOT(ISNUMBER(H9))),"⚠ Hauteur d'allège manquante",IF(AND(E9<>"Fenêtre de toit",IF($B9="R+1",N(Projet!$B$61),N(Projet!$B$60))>0,N(H9)+G9>IF($B9="R+1",N(Projet!$B$61),N(Projet!$B$60))*1000),"⚠ Dépasse la hauteur sous plafond",IF(J9="","⚠ Préciser tableau / hors tout","OK"))))))
M10: =IF(AND(ISNUMBER(F10),ISNUMBER(G10)),F10*G10/1000000,"") | N10: =IF(M10="","",M10*IF(ISNUMBER(L10),L10,1)) | O10: =IF(COUNTA(A10:L10)=0,"",IF(OR(NOT(ISNUMBER(F10)),NOT(ISNUMBER(G10))),"⚠ Largeur ou hauteur manquante",IF(C10="","⚠ Façade manquante",IF(AND(OR(E10="Fenêtre",E10="Châssis fixe"),NOT(ISNUMBER(H10))),"⚠ Hauteur d'allège manquante",IF(AND(E10<>"Fenêtre de toit",IF($B10="R+1",N(Projet!$B$61),N(Projet!$B$60))>0,N(H10)+G10>IF($B10="R+1",N(Projet!$B$61),N(Projet!$B$60))*1000),"⚠ Dépasse la hauteur sous plafond",IF(J10="","⚠ Préciser tableau / hors tout","OK"))))))
M11: =IF(AND(ISNUMBER(F11),ISNUMBER(G11)),F11*G11/1000000,"") | N11: =IF(M11="","",M11*IF(ISNUMBER(L11),L11,1)) | O11: =IF(COUNTA(A11:L11)=0,"",IF(OR(NOT(ISNUMBER(F11)),NOT(ISNUMBER(G11))),"⚠ Largeur ou hauteur manquante",IF(C11="","⚠ Façade manquante",IF(AND(OR(E11="Fenêtre",E11="Châssis fixe"),NOT(ISNUMBER(H11))),"⚠ Hauteur d'allège manquante",IF(AND(E11<>"Fenêtre de toit",IF($B11="R+1",N(Projet!$B$61),N(Projet!$B$60))>0,N(H11)+G11>IF($B11="R+1",N(Projet!$B$61),N(Projet!$B$60))*1000),"⚠ Dépasse la hauteur sous plafond",IF(J11="","⚠ Préciser tableau / hors tout","OK"))))))
M12: =IF(AND(ISNUMBER(F12),ISNUMBER(G12)),F12*G12/1000000,"") | N12: =IF(M12="","",M12*IF(ISNUMBER(L12),L12,1)) | O12: =IF(COUNTA(A12:L12)=0,"",IF(OR(NOT(ISNUMBER(F12)),NOT(ISNUMBER(G12))),"⚠ Largeur ou hauteur manquante",IF(C12="","⚠ Façade manquante",IF(AND(OR(E12="Fenêtre",E12="Châssis fixe"),NOT(ISNUMBER(H12))),"⚠ Hauteur d'allège manquante",IF(AND(E12<>"Fenêtre de toit",IF($B12="R+1",N(Projet!$B$61),N(Projet!$B$60))>0,N(H12)+G12>IF($B12="R+1",N(Projet!$B$61),N(Projet!$B$60))*1000),"⚠ Dépasse la hauteur sous plafond",IF(J12="","⚠ Préciser tableau / hors tout","OK"))))))
M13: =IF(AND(ISNUMBER(F13),ISNUMBER(G13)),F13*G13/1000000,"") | N13: =IF(M13="","",M13*IF(ISNUMBER(L13),L13,1)) | O13: =IF(COUNTA(A13:L13)=0,"",IF(OR(NOT(ISNUMBER(F13)),NOT(ISNUMBER(G13))),"⚠ Largeur ou hauteur manquante",IF(C13="","⚠ Façade manquante",IF(AND(OR(E13="Fenêtre",E13="Châssis fixe"),NOT(ISNUMBER(H13))),"⚠ Hauteur d'allège manquante",IF(AND(E13<>"Fenêtre de toit",IF($B13="R+1",N(Projet!$B$61),N(Projet!$B$60))>0,N(H13)+G13>IF($B13="R+1",N(Projet!$B$61),N(Projet!$B$60))*1000),"⚠ Dépasse la hauteur sous plafond",IF(J13="","⚠ Préciser tableau / hors tout","OK"))))))
M14: =IF(AND(ISNUMBER(F14),ISNUMBER(G14)),F14*G14/1000000,"") | N14: =IF(M14="","",M14*IF(ISNUMBER(L14),L14,1)) | O14: =IF(COUNTA(A14:L14)=0,"",IF(OR(NOT(ISNUMBER(F14)),NOT(ISNUMBER(G14))),"⚠ Largeur ou hauteur manquante",IF(C14="","⚠ Façade manquante",IF(AND(OR(E14="Fenêtre",E14="Châssis fixe"),NOT(ISNUMBER(H14))),"⚠ Hauteur d'allège manquante",IF(AND(E14<>"Fenêtre de toit",IF($B14="R+1",N(Projet!$B$61),N(Projet!$B$60))>0,N(H14)+G14>IF($B14="R+1",N(Projet!$B$61),N(Projet!$B$60))*1000),"⚠ Dépasse la hauteur sous plafond",IF(J14="","⚠ Préciser tableau / hors tout","OK"))))))
M15: =IF(AND(ISNUMBER(F15),ISNUMBER(G15)),F15*G15/1000000,"") | N15: =IF(M15="","",M15*IF(ISNUMBER(L15),L15,1)) | O15: =IF(COUNTA(A15:L15)=0,"",IF(OR(NOT(ISNUMBER(F15)),NOT(ISNUMBER(G15))),"⚠ Largeur ou hauteur manquante",IF(C15="","⚠ Façade manquante",IF(AND(OR(E15="Fenêtre",E15="Châssis fixe"),NOT(ISNUMBER(H15))),"⚠ Hauteur d'allège manquante",IF(AND(E15<>"Fenêtre de toit",IF($B15="R+1",N(Projet!$B$61),N(Projet!$B$60))>0,N(H15)+G15>IF($B15="R+1",N(Projet!$B$61),N(Projet!$B$60))*1000),"⚠ Dépasse la hauteur sous plafond",IF(J15="","⚠ Préciser tableau / hors tout","OK"))))))
M16: =IF(AND(ISNUMBER(F16),ISNUMBER(G16)),F16*G16/1000000,"") | N16: =IF(M16="","",M16*IF(ISNUMBER(L16),L16,1)) | O16: =IF(COUNTA(A16:L16)=0,"",IF(OR(NOT(ISNUMBER(F16)),NOT(ISNUMBER(G16))),"⚠ Largeur ou hauteur manquante",IF(C16="","⚠ Façade manquante",IF(AND(OR(E16="Fenêtre",E16="Châssis fixe"),NOT(ISNUMBER(H16))),"⚠ Hauteur d'allège manquante",IF(AND(E16<>"Fenêtre de toit",IF($B16="R+1",N(Projet!$B$61),N(Projet!$B$60))>0,N(H16)+G16>IF($B16="R+1",N(Projet!$B$61),N(Projet!$B$60))*1000),"⚠ Dépasse la hauteur sous plafond",IF(J16="","⚠ Préciser tableau / hors tout","OK"))))))
M17: =IF(AND(ISNUMBER(F17),ISNUMBER(G17)),F17*G17/1000000,"") | N17: =IF(M17="","",M17*IF(ISNUMBER(L17),L17,1)) | O17: =IF(COUNTA(A17:L17)=0,"",IF(OR(NOT(ISNUMBER(F17)),NOT(ISNUMBER(G17))),"⚠ Largeur ou hauteur manquante",IF(C17="","⚠ Façade manquante",IF(AND(OR(E17="Fenêtre",E17="Châssis fixe"),NOT(ISNUMBER(H17))),"⚠ Hauteur d'allège manquante",IF(AND(E17<>"Fenêtre de toit",IF($B17="R+1",N(Projet!$B$61),N(Projet!$B$60))>0,N(H17)+G17>IF($B17="R+1",N(Projet!$B$61),N(Projet!$B$60))*1000),"⚠ Dépasse la hauteur sous plafond",IF(J17="","⚠ Préciser tableau / hors tout","OK"))))))
... M65: =IF(AND(ISNUMBER(F65),ISNUMBER(G65)),F65*G65/1000000,"") | N65: =IF(M65="","",M65*IF(ISNUMBER(L65),L65,1)) | O65: =IF(COUNTA(A65:L65)=0,"",IF(OR(NOT(ISNUMBER(F65)),NOT(ISNUMBER(G65))),"⚠ Largeur ou hauteur manquante",IF(C65="","⚠ Façade manquante",IF(AND(OR(E65="Fenêtre",E65="Châssis fixe"),NOT(ISNUMBER(H65))),"⚠ Hauteur d'allège manquante",IF(AND(E65<>"Fenêtre de toit",IF($B65="R+1",N(Projet!$B$61),N(Projet!$B$60))>0,N(H65)+G65>IF($B65="R+1",N(Projet!$B$61),N(Projet!$B$60))*1000),"⚠ Dépasse la hauteur sous plafond",IF(J65="","⚠ Préciser tableau / hors tout","OK"))))))
A67: TOTAL | K67: Nb d'ouvertures | L67: =SUMIFS(L6:L65,F6:F65,">0")+COUNTIFS(F6:F65,">0",L6:L65,"") | N67: =SUM(N6:N65) | O67: =COUNTIF(O6:O65,"⚠*")&" ligne(s) à corriger"

Sheet Façades et planchers
A1: Façades, murs de refend et planchers
A2: Cotes extérieures en mètres. Les surfaces d'ouvertures sont reprises automatiquement de l'onglet « Ouvertures ». Si une façade comporte un pignon, indiquer la hauteur du pignon (du haut du mur au faîtage) : il est compté comme un triangle.
A4: A. Façades
A5: Façade | B5: Longueur (m) | C5: Hauteur mur RDC (m) | D5: Hauteur mur étage (m) | E5: Pignon ? | F5: Hauteur du pignon (m) | G5: Surface brute (m²) | H5: Surface ouvertures (m²) | I5: Surface nette (m²) | J5: % vitré
A6: Nord | G6: =N(B6)*(N(C6)+N(D6))+IF(E6="Oui",N(B6)*N(F6)/2,0) | H6: =SUMIFS(Ouvertures!$N$6:$N$65,Ouvertures!$C$6:$C$65,A6) | I6: =G6-H6 | J6: =IF(G6>0,H6/G6,"")
A7: Sud | G7: =N(B7)*(N(C7)+N(D7))+IF(E7="Oui",N(B7)*N(F7)/2,0) | H7: =SUMIFS(Ouvertures!$N$6:$N$65,Ouvertures!$C$6:$C$65,A7) | I7: =G7-H7 | J7: =IF(G7>0,H7/G7,"")
A8: Est | G8: =N(B8)*(N(C8)+N(D8))+IF(E8="Oui",N(B8)*N(F8)/2,0) | H8: =SUMIFS(Ouvertures!$N$6:$N$65,Ouvertures!$C$6:$C$65,A8) | I8: =G8-H8 | J8: =IF(G8>0,H8/G8,"")
A9: Ouest | G9: =N(B9)*(N(C9)+N(D9))+IF(E9="Oui",N(B9)*N(F9)/2,0) | H9: =SUMIFS(Ouvertures!$N$6:$N$65,Ouvertures!$C$6:$C$65,A9) | I9: =G9-H9 | J9: =IF(G9>0,H9/G9,"")
A10: Autre | G10: =N(B10)*(N(C10)+N(D10))+IF(E10="Oui",N(B10)*N(F10)/2,0) | H10: =SUMIFS(Ouvertures!$N$6:$N$65,Ouvertures!$C$6:$C$65,A10) | I10: =G10-H10 | J10: =IF(G10>0,H10/G10,"")
A11: TOTAL | B11: =SUM(B6:B10) | G11: =SUM(G6:G10) | H11: =SUM(H6:H10) | I11: =SUM(I6:I10) | J11: =IF(G11>0,H11/G11,"")
A12: Contrôle : périmètre (Nord + Sud + Est + Ouest) = | E12: =SUM(B6:B9)
A15: B. Murs de refend porteurs (murs intérieurs qui portent un plancher ou la charpente)
A16: Repère | B16: Niveau | C16: Longueur (m) | D16: Hauteur (m) | E16: Ouverture (porte) ?
A23: Linéaire total | C23: =SUM(C17:C22)
A26: C. Planchers
A27: Plancher | B27: Surface (m²) | C27: Plus grande portée (m) | D27: Usage | E27: Revêtement prévu
A28: Plancher bas (si vide sanitaire) | G28: La portée = distance libre entre deux appuis (murs porteurs ou poutres).
A29: Plancher R+1 | G29: Carrelage et chape alourdissent fortement le plancher : merci de les signaler.
A30: Plancher combles

Sheet Interne
A1: QUALIFICATION INTERNE BLOKIWOOD — onglet masqué, ne pas transmettre
A3: Critère | B3: Réponse du client | C3: Points | D3: Max | F3: Barème (clé|réponse) | G3: Points
A4: Niveau d'avancement | B4: =Projet!$B$24&"" | C4: =IFERROR(VLOOKUP("avancement|"&Projet!$B$24,$F$4:$G$26,2,FALSE),0) | D4: 25 | F4: avancement|Idée | G4: 0
A5: Statut du terrain | B5: =Projet!$B$17&"" | C5: =IFERROR(VLOOKUP("t_statut|"&Projet!$B$17,$F$4:$G$26,2,FALSE),0) | D5: 10 | F5: avancement|Terrain trouvé | G5: 5
A6: Financement (accord bancaire ou fonds propres) | B6: =Projet!$B$38&" / "&Projet!$B$39 | C6: =IF(Projet!$B$38="Fonds propres",15,IFERROR(VLOOKUP("fin_accord|"&Projet!$B$39,$F$4:$G$26,2,FALSE),0)) | D6: 15 | F6: avancement|Terrain acquis | G6: 10
A7: Étude de sol G2 | B7: =Projet!$B$28&"" | C7: =IFERROR(VLOOKUP("sol|"&Projet!$B$28,$F$4:$G$26,2,FALSE),0) | D7: 10 | F7: avancement|PC en préparation | G7: 15
A8: Montage du kit | B8: =Projet!$B$32&"" | C8: =IFERROR(VLOOKUP("pose|"&Projet!$B$32,$F$4:$G$26,2,FALSE),0) | D8: 10 | F8: avancement|PC déposé | G8: 20
A9: Assurance dommages-ouvrage | B9: =Projet!$B$40&"" | C9: =IFERROR(VLOOKUP("do|"&Projet!$B$40,$F$4:$G$26,2,FALSE),0) | D9: 5 | F9: avancement|PC obtenu | G9: 25
A10: Début des fondations sous 12 mois | B10: =IF(ISNUMBER(Projet!$B$43),Projet!$B$43,"") | C10: =IF(AND(ISNUMBER(Projet!$B$43),Projet!$B$43-TODAY()<=365),5,0) | D10: 5 | F10: t_statut|Acquis | G10: 10
A11: Pièces jointes fournies (sur 7) | B11: =(Projet!$B$87="Joint")+(Projet!$B$88="Joint")+(Projet!$B$89="Joint")+(Projet!$B$90="Joint")+(Projet!$B$91="Joint")+(Projet!$B$92="Joint")+(Projet!$B$93="Joint") | C11: =ROUND(((Projet!$B$87="Joint")+(Projet!$B$88="Joint")+(Projet!$B$89="Joint")+(Projet!$B$90="Joint")+(Projet!$B$91="Joint")+(Projet!$B$92="Joint")+(Projet!$B$93="Joint"))/7*10,0) | D11: 10 | F11: t_statut|Sous compromis | G11: 6
A12: Taux de complétion du dossier | B12: =Projet!$B$4 | C12: =ROUND(Projet!$B$4*10,0) | D12: 10 | F12: t_statut|En recherche | G12: 0
A13: SCORE DE MATURITÉ | C13: =SUM(C4:C12) | D13: =SUM(D4:D12) | F13: fin_accord|Oui | G13: 15
A14: Verdict | B14: =IF(C13>=65,"Projet mûr : prioritaire",IF(C13>=40,"Projet en cours : chiffrer puis relancer","Projet précoce : proposer une étude payante")) | F14: fin_accord|En cours | G14: 8
A15: Seuils : 65 et plus = mûr ; 40 à 64 = en cours ; moins de 40 = précoce. | F15: fin_accord|Non | G15: 0
F16: sol|Réalisée | G16: 10
A17: Infos commerciales | F17: sol|Commandée | G17: 6
A18: Budget annoncé | B18: =Projet!$B$37 | F18: sol|Non | G18: 0
A19: Budget / m² habitable | B19: =IF(AND(N(Projet!$B$37)>0,N(Projet!$B$57)>0),Projet!$B$37/Projet!$B$57,"") | F19: pose|Artisan choisi | G19: 10
A20: Autres devis demandés | B20: =Projet!$B$45&"" | F20: pose|Auto-construction | G20: 6
A21: Date de décision annoncée | B21: =IF(ISNUMBER(Projet!$B$46),Projet!$B$46,"") | F21: pose|Recherche d'un poseur | G21: 4
A22: Nombre d'ouvertures saisies | B22: =Ouvertures!$L$67 | F22: pose|À définir | G22: 0
A23: Lignes d'ouvertures à corriger | B23: =COUNTIF(Ouvertures!$O$6:$O$65,"⚠*") | F23: do|Oui | G23: 5
A24: Surface murs extérieurs (m²) | B24: ='Façades et planchers'!$G$11 | F24: do|En cours | G24: 3
F25: do|Non | G25: 0
A26: Note : un budget inférieur à ~1 500 €/m² habitable pour une maison complète mérite d'être questionné. | F26: do|Ne sais pas | G26: 0
F27: Points modifiables (texte bleu).
